Workbook
Name Вид_изделия: Диапазоны!$C$2:$C$7
Name Название: Рецепты[Название]
Name Название_ингредиента: Ингредиенты!$A$2:$A$1048576
Name Рецепты_для_Москит: Диапазоны!$K$25
Name Способ_приготовления: Диапазоны!$E$2:$E$1048576
Name Срез_Вид: #N/A
Name Срез_Вид1: #N/A
Name Срез_Вид2: #N/A
Name Срез_Где_покупать: #N/A
Name Срез_Название: #N/A
Name Срез_Название1: #N/A
Name Срез_Наличие: #N/A
Name Срез_Способ: #N/A
Name Срез_Способ1: #N/A
Name Срез_Способ2: #N/A
Name Срез_Сырье: #N/A
Name Сырье: Диапазоны!$A$2:$A$1048576

Sheet Диапазоны
A1: Сырье | C1: Вид изделия | E1: Способ приготовления | F1: Потери | G1: Маржа | J1: ГК | K1: ХК
A2: Баранина | C2: Колбаса | E2: Вареное | F2: 0.15 | G2: 0.7 | J2: Сушка при +20 до потери веса 10% | K2: Солим
A3: Говядина | C3: Рыба | E3: ГК | F3: 0.15 | G3: 0.9 | J3: Отепление при +35 до +22 внутри | K3: ...Вымачиваем...
A4: Добавки | C4: Цельное | E4: Соленое | F4: 0.05 | G4: 0.5 | J4: Сушка при +60 до +40 внутри | K4: Сушка при +20 до потери веса 10%
A5: Оболочка | C5: Сосиски | E5: Сырокопченое | F5: 0.35 | G5: 2 | J5: Коптим без статики при +80 в течение 1 часа | K5: Копчение при +20 с электростатикой 1 час
A6: Птица | C6: Сыр | E6: Сыровяленное | F6: 0.35 | G6: 2 | J6: Варка при +90 - +110 до +70 внутри | K6: В холодильник на сутки
A7: Рыба | C7: Еда | E7: ХК | F7: 0.15 | G7: 1 | J7: Душируем в ледяной воде до +20 внутри
A8: Свинина | E8: Провесная | F8: 0.1 | G8: 0.9
A9: Специи | E9: Сыр | F9: 0.92 | G9: 3
E10: Еда | F10: 0.05 | G10: 0.5
K25: Рецепты для Москит от Строгой

Sheet Ингредиенты
A1: Название ингредиента | B1: Сырье | C1: Цена | D1: Тип сырья | E1: Где покупать | F1: Ссылка | G1: Обьем | H1: Цена/Обьем | I1: Наличие | J1: Выход
A2: Карбонад свиной | B2: Свинина | C2: =IFERROR(IF(Ингредиенты[[#This Row],[Выход]]<>"",(Ингредиенты[[#This Row],[Цена/Обьем]]/Ингредиенты[[#This Row],[Обьем]]*100%/Ингредиенты[[#This Row],[Выход]]),Ингредиенты[[#This Row],[Цена/Обьем]]/Ингредиенты[[#This Row],[Обьем]]),"") -> 0.39999 | D2: Основа | E2: Европа | G2: 1000 | H2: 399.99 | I2: Нет
A3: Окорок свиной | B3: Свинина | C3: =IFERROR(IF(Ингредиенты[[#This Row],[Выход]]<>"",(Ингредиенты[[#This Row],[Цена/Обьем]]/Ингредиенты[[#This Row],[Обьем]]*100%/Ингредиенты[[#This Row],[Выход]]),Ингредиенты[[#This Row],[Цена/Обьем]]/Ингредиенты[[#This Row],[Обьем]]),"") -> 0.369 | D3: Основа | E3: Обуховский | G3: 1000 | H3: 369 | I3: Да
A4: Лопатка свиная | B4: Свинина | C4: =IFERROR(IF(Ингредиенты[[#This Row],[Выход]]<>"",(Ингредиенты[[#This Row],[Цена/Обьем]]/Ингредиенты[[#This Row],[Обьем]]*100%/Ингредиенты[[#This Row],[Выход]]),Ингредиенты[[#This Row],[Цена/Обьем]]/Ингредиенты[[#This Row],[Обьем]]),"") -> 0.369 | D4: Основа | E4: Европа | G4: 1000 | H4: 369 | I4: Нет
A5: Шея свиная | B5: Свинина | C5: =IFERROR(IF(Ингредиенты[[#This Row],[Выход]]<>"",(Ингредиенты[[#This Row],[Цена/Обьем]]/Ингредиенты[[#This Row],[Обьем]]*100%/Ингредиенты[[#This Row],[Выход]]),Ингредиенты[[#This Row],[Цена/Обьем]]/Ингредиенты[[#This Row],[Обьем]]),"") -> 0.58 | D5: Основа | E5: Европа | G5: 1000 | H5: 580 | I5: Нет
A6: Грудинка свиная | B6: Свинина | C6: =IFERROR(IF(Ингредиенты[[#This Row],[Выход]]<>"",(Ингредиенты[[#This Row],[Цена/Обьем]]/Ингредиенты[[#This Row],[Обьем]]*100%/Ингредиенты[[#This Row],[Выход]]),Ингредиенты[[#This Row],[Цена/Обьем]]/Ингредиенты[[#This Row],[Обьем]]),"") -> 0.42999 | D6: Основа | E6: Европа | G6: 1000 | H6: 429.99 | I6: Нет
A7: Ребра свиные | B7: Свинина | C7: =IFERROR(IF(Ингредиенты[[#This Row],[Выход]]<>"",(Ингредиенты[[#This Row],[Цена/Обьем]]/Ингредиенты[[#This Row],[Обьем]]*100%/Ингредиенты[[#This Row],[Выход]]),Ингредиенты[[#This Row],[Цена/Обьем]]/Ингредиенты[[#This Row],[Обьем]]),"") -> 0.28999 | D7: Основа | E7: Европа | F7: Грудинка свиная б/к с/ш, собственное производство - купить онлайн с доставкой по цене 429.99 в интернет-магазине ЕВРОПА | G7: 1000 | H7: 289.99 | I7: Нет
A8: Рулька свиная | B8: Свинина | C8: =IFERROR(IF(Ингредиенты[[#This Row],[Выход]]<>"",(Ингредиенты[[#This Row],[Цена/Обьем]]/Ингредиенты[[#This Row],[Обьем]]*100%/Ингредиенты[[#This Row],[Выход]]),Ингредиенты[[#This Row],[Цена/Обьем]]/Ингредиенты[[#This Row],[Обьем]]),"") -> 0.27999 | D8: Основа | E8: Европа | F8: Свинина рулька собственное производство - купить онлайн с доставкой по цене 239.99 в интернет-магазине ЕВРОПА | G8: 1000 | H8: 279.99 | I8: Нет
A9: Сало свиное | B9: Свинина | C9: =IFERROR(IF(Ингредиенты[[#This Row],[Выход]]<>"",(Ингредиенты[[#This Row],[Цена/Обьем]]/Ингредиенты[[#This Row],[Обьем]]*100%/Ингредиенты[[#This Row],[Выход]]),Ингредиенты[[#This Row],[Цена/Обьем]]/Ингредиенты[[#This Row],[Обьем]]),"") -> 0.3 | D9: Основа | E9: Авито | G9: 1000 | H9: 300 | I9: Да
A10: Шпик | B10: Свинина | C10: =IFERROR(IF(Ингредиенты[[#This Row],[Выход]]<>"",(Ингредиенты[[#This Row],[Цена/Обьем]]/Ингредиенты[[#This Row],[Обьем]]*100%/Ингредиенты[[#This Row],[Выход]]),Ингредиенты[[#This Row],[Цена/Обьем]]/Ингредиенты[[#This Row],[Обьем]]),"") -> 0.3 | D10: Основа | E10: Авито | G10: 1000 | H10: 300 | I10: Нет
A11: Швартенблок | B11: Свинина | C11: =IFERROR(IF(Ингредиенты[[#This Row],[Выход]]<>"",(Ингредиенты[[#This Row],[Цена/Обьем]]/Ингредиенты[[#This Row],[Обьем]]*100%/Ингредиенты[[#This Row],[Выход]]),Ингредиенты[[#This Row],[Цена/Обьем]]/Ингредиенты[[#This Row],[Обьем]]),"") -> 0.3 | D11: Основа | E11: Сам делаю | G11: 1000 | H11: 300 | I11: Нет
A12: Шкуры, голова, обрезь | B12: Свинина | C12: =IFERROR(IF(Ингредиенты[[#This Row],[Выход]]<>"",(Ингредиенты[[#This Row],[Цена/Обьем]]/Ингредиенты[[#This Row],[Обьем]]*100%/Ингредиенты[[#This Row],[Выход]]),Ингредиенты[[#This Row],[Цена/Обьем]]/Ингредиенты[[#This Row],[Обьем]]),"") -> 0.1 | D12: Основа | E12: Сам делаю | G12: 1000 | H12: 100 | I12: Да
A13: Говядина | B13: Говядина | C13: =IFERROR(IF(Ингредиенты[[#This Row],[Выход]]<>"",(Ингредиенты[[#This Row],[Цена/Обьем]]/Ингредиенты[[#This Row],[Обьем]]*100%/Ингредиенты[[#This Row],[Выход]]),Ингредиенты[[#This Row],[Цена/Обьем]]/Ингредиенты[[#This Row],[Обьем]]),"") -> 0.70999 | D13: Основа | E13: Европа | G13: 1000 | H13: 709.99 | I13: Да
A14: Язык говяжий | B14: Говядина | C14: =IFERROR(IF(Ингредиенты[[#This Row],[Выход]]<>"",(Ингредиенты[[#This Row],[Цена/Обьем]]/Ингредиенты[[#This Row],[Обьем]]*100%/Ингредиенты[[#This Row],[Выход]]),Ингредиенты[[#This Row],[Цена/Обьем]]/Ингредиенты[[#This Row],[Обьем]]),"") -> 1.09999 | D14: Основа | E14: Европа | G14: 1000 | H14: 1099.99 | I14: Нет
A15: Жир говяжий | B15: Говядина | C15: =IFERROR(IF(Ингредиенты[[#This Row],[Выход]]<>"",(Ингредиенты[[#This Row],[Цена/Обьем]]/Ингредиенты[[#This Row],[Обьем]]*100%/Ингредиенты[[#This Row],[Выход]]),Ингредиенты[[#This Row],[Цена/Обьем]]/Ингредиенты[[#This Row],[Обьем]]),"") -> 0.25 | D15: Основа | E15: Обрезки | G15: 1000 | H15: 250 | I15: Нет
A16: Баранина | B16: Баранина | C16: =IFERROR(IF(Ингредиенты[[#This Row],[Выход]]<>"",(Ингредиенты[[#This Row],[Цена/Обьем]]/Ингредиенты[[#This Row],[Обьем]]*100%/Ингредиенты[[#This Row],[Выход]]),Ингредиенты[[#This Row],[Цена/Обьем]]/Ингредиенты[[#This Row],[Обьем]]),"") -> 0.70588235 | D16: Основа | E16: Авито | G16: 1000 | H16: 480 | I16: Нет | J16: 0.68
A17: Гусь | B17: Птица | C17: =IFERROR(IF(Ингредиенты[[#This Row],[Выход]]<>"",(Ингредиенты[[#This Row],[Цена/Обьем]]/Ингредиенты[[#This Row],[Обьем]]*100%/Ингредиенты[[#This Row],[Выход]]),Ингредиенты[[#This Row],[Цена/Обьем]]/Ингредиенты[[#This Row],[Обьем]]),"") -> 0.9 | D17: Основа | G17: 1000 | H17: 900
A18: Курица целая | B18: Птица | C18: =IFERROR(IF(Ингредиенты[[#This Row],[Выход]]<>"",(Ингредиенты[[#This Row],[Цена/Обьем]]/Ингредиенты[[#This Row],[Обьем]]*100%/Ингредиенты[[#This Row],[Выход]]),Ингредиенты[[#This Row],[Цена/Обьем]]/Ингредиенты[[#This Row],[Обьем]]),"") -> 0.2 | D18: Основа | E18: Европа | F18: Тушка ц/б 1 кат охл - купить онлайн с доставкой по цене 179.99 в интернет-магазине ЕВРОПА | G18: 1000 | H18: 200 | I18: Да
A19: Грудка куриная | B19: Птица | C19: =IFERROR(IF(Ингредиенты[[#This Row],[Выход]]<>"",(Ингредиенты[[#This Row],[Цена/Обьем]]/Ингредиенты[[#This Row],[Обьем]]*100%/Ингредиенты[[#This Row],[Выход]]),Ингредиенты[[#This Row],[Цена/Обьем]]/Ингредиенты[[#This Row],[Обьем]]),"") -> 0.27999 | D19: Основа | E19: Европа | G19: 1000 | H19: 279.99 | I19: Нет
A20: Бедра куриные | B20: Птица | C20: =IFERROR(IF(Ингредиенты[[#This Row],[Выход]]<>"",(Ингредиенты[[#This Row],[Цена/Обьем]]/Ингредиенты[[#This Row],[Обьем]]*100%/Ингредиенты[[#This Row],[Выход]]),Ингредиенты[[#This Row],[Цена/Обьем]]/Ингредиенты[[#This Row],[Обьем]]),"") -> 0.26117647 | D20: Основа | E20: Европа | G20: 1000 | H20: 222 | I20: Нет | J20: 0.85
A21: Индейка | B21: Птица | C21: =IFERROR(IF(Ингредиенты[[#This Row],[Выход]]<>"",(Ингредиенты[[#This Row],[Цена/Обьем]]/Ингредиенты[[#This Row],[Обьем]]*100%/Ингредиенты[[#This Row],[Выход]]),Ингредиенты[[#This Row],[Цена/Обьем]]/Ингредиенты[[#This Row],[Обьем]]),"") -> 0.56999 | D21: Основа | E21: Европа | G21: 1000 | H21: 569.99 | I21: Нет
A22: Скумбрия | B22: Рыба | C22: =IFERROR(IF(Ингредиенты[[#This Row],[Выход]]<>"",(Ингредиенты[[#This Row],[Цена/Обьем]]/Ингредиенты[[#This Row],[Обьем]]*100%/Ингредиенты[[#This Row],[Выход]]),Ингредиенты[[#This Row],[Цена/Обьем]]/Ингредиенты[[#This Row],[Обьем]]),"") -> 0.425 | D22: Основа | E22: Европа | G22: 1000 | H22: 340 | I22: Нет | J22: 0.8
A23: Горбуша | B23: Рыба | C23: =IFERROR(IF(Ингредиенты[[#This Row],[Выход]]<>"",(Ингредиенты[[#This Row],[Цена/Обьем]]/Ингредиенты[[#This Row],[Обьем]]*100%/Ингредиенты[[#This Row],[Выход]]),Ингредиенты[[#This Row],[Цена/Обьем]]/Ингредиенты[[#This Row],[Обьем]]),"") -> 0.37855714 | D23: Основа | E23: Европа | G23: 1000 | H23: 264.99 | I23: Нет | J23: 0.7
A24: Сельдь | B24: Рыба | C24: =IFERROR(IF(Ингредиенты[[#This Row],[Выход]]<>"",(Ингредиенты[[#This Row],[Цена/Обьем]]/Ингредиенты[[#This Row],[Обьем]]*100%/Ингредиенты[[#This Row],[Выход]]),Ингредиенты[[#This Row],[Цена/Обьем]]/Ингредиенты[[#This Row],[Обьем]]),"") -> 0.34285714 | D24: Основа | E24: Европа | G24: 1000 | H24: 240 | I24: Нет | J24: 0.7
A25: Карп | B25: Рыба | C25: =IFERROR(IF(Ингредиенты[[#This Row],[Выход]]<>"",(Ингредиенты[[#This Row],[Цена/Обьем]]/Ингредиенты[[#This Row],[Обьем]]*100%/Ингредиенты[[#This Row],[Выход]]),Ингредиенты[[#This Row],[Цена/Обьем]]/Ингредиенты[[#This Row],[Обьем]]),"") -> 0.49998333 | D25: Основа | E25: Европа | G25: 1000 | H25: 299.99 | I25: Да | J25: 0.6
A26: Белый амур | B26: Рыба | C26: =IFERROR(IF(Ингредиенты[[#This Row],[Выход]]<>"",(Ингредиенты[[#This Row],[Цена/Обьем]]/Ингредиенты[[#This Row],[Обьем]]*100%/Ингредиенты[[#This Row],[Выход]]),Ингредиенты[[#This Row],[Цена/Обьем]]/Ингредиенты[[#This Row],[Обьем]]),"") -> 0.66666667 | D26: Основа | G26: 1000 | H26: 400 | I26: Да | J26: 0.6
A27: Карась | B27: Рыба | C27: =IFERROR(IF(Ингредиенты[[#This Row],[Выход]]<>"",(Ингредиенты[[#This Row],[Цена/Обьем]]/Ингредиенты[[#This Row],[Обьем]]*100%/Ингредиенты[[#This Row],[Выход]]),Ингредиенты[[#This Row],[Цена/Обьем]]/Ингредиенты[[#This Row],[Обьем]]),"") -> 0.25 | D27: Основа | E27: Авито | G27: 1000 | H27: 150 | I27: Да | J27: 0.6
A28: Щука | B28: Рыба | C28: =IFERROR(IF(Ингредиенты[[#This Row],[Выход]]<>"",(Ингредиенты[[#This Row],[Цена/Обьем]]/Ингредиенты[[#This Row],[Обьем]]*100%/Ингредиенты[[#This Row],[Выход]]),Ингредиенты[[#This Row],[Цена/Обьем]]/Ингредиенты[[#This Row],[Обьем]]),"") -> 0.30769231 | D28: Основа | E28: Авито | G28: 1000 | H28: 200 | I28: Да | J28: 0.65
A29: Форель | B29: Рыба | C29: =IFERROR(IF(Ингредиенты[[#This Row],[Выход]]<>"",(Ингредиенты[[#This Row],[Цена/Обьем]]/Ингредиенты[[#This Row],[Обьем]]*100%/Ингредиенты[[#This Row],[Выход]]),Ингредиенты[[#This Row],[Цена/Обьем]]/Ингредиенты[[#This Row],[Обьем]]),"") -> 1.37375 | D29: Основа | E29: Европа | F29: Форель с\м б/г крупная - купить онлайн с доставкой по цене 1099.99 в интернет-магазине ЕВРОПА | G29: 1000 | H29: 1099 | I29: Нет | J29: 0.8
A30: Рис круглозерновой | B30: Добавки | C30: =IFERROR(IF(Ингредиенты[[#This Row],[Выход]]<>"",(Ингредиенты[[#This Row],[Цена/Обьем]]/Ингредиенты[[#This Row],[Обьем]]*100%/Ингредиенты[[#This Row],[Выход]]),Ингредиенты[[#This Row],[Цена/Обьем]]/Ингредиенты[[#This Row],[Обьем]]),"") -> 0.24444444 | D30: Основа | G30: 900 | H30: 220
A31: Перловка | B31: Добавки | C31: =IFERROR(IF(Ингредиенты[[#This Row],[Выход]]<>"",(Ингредиенты[[#This Row],[Цена/Обьем]]/Ингредиенты[[#This Row],[Обьем]]*100%/Ингредиенты[[#This Row],[Выход]]),Ингредиенты[[#This Row],[Цена/Обьем]]/Ингредиенты[[#This Row],[Обьем]]),"") -> 0.04125 | D31: Основа | E31: Европа | F31: Крупа перловая Европа 800г - купить онлайн с доставкой по цене 33 в интернет-магазине ЕВРОПА (europa-market.ru) | G31: 800 | H31: 33 | I31: Да
A32: Картофель | B32: Добавки | C32: =IFERROR(IF(Ингредиенты[[#This Row],[Выход]]<>"",(Ингредиенты[[#This Row],[Цена/Обьем]]/Ингредиенты[[#This Row],[Обьем]]*100%/Ингредиенты[[#This Row],[Выход]]),Ингредиенты[[#This Row],[Цена/Обьем]]/Ингредиенты[[#This Row],[Обьем]]),"") -> 0.03999 | D32: Основа | E32: Европа | F32: Картофель вес - купить онлайн с доставкой по цене 39.99 в интернет-магазине ЕВРОПА (europa-market.ru) | G32: 1000 | H32: 39.99 | I32: Да
A33: Молоко | B33: Добавки | C33: =IFERROR(IF(Ингредиенты[[#This Row],[Выход]]<>"",(Ингредиенты[[#This Row],[Цена/Обьем]]/Ингредиенты[[#This Row],[Обьем]]*100%/Ингредиенты[[#This Row],[Выход]]),Ингредиенты[[#This Row],[Цена/Обьем]]/Ингредиенты[[#This Row],[Обьем]]),"") -> 0.06666 | D33: Основа | E33: Панарин | G33: 1000 | H33: 66.66 | I33: Да
A34: Морковь | B34: Специи | C34: =IFERROR(IF(Ингредиенты[[#This Row],[Выход]]<>"",(Ингредиенты[[#This Row],[Цена/Обьем]]/Ингредиенты[[#This Row],[Обьем]]*100%/Ингредиенты[[#This Row],[Выход]]),Ингредиенты[[#This Row],[Цена/Обьем]]/Ингредиенты[[#This Row],[Обьем]]),"") -> 0.02999 | D34: Добавка | E34: Европа | F34: Морковь вес - купить онлайн с доставкой по цене 29.99 в интернет-магазине ЕВРОПА (europa-market.ru) | G34: 1000 | H34: 29.99 | I34: Да
A35: Сливочное масло | B35: Добавки | C35: =IFERROR(IF(Ингредиенты[[#This Row],[Выход]]<>"",(Ингредиенты[[#This Row],[Цена/Обьем]]/Ингредиенты[[#This Row],[Обьем]]*100%/Ингредиенты[[#This Row],[Выход]]),Ингредиенты[[#This Row],[Цена/Обьем]]/Ингредиенты[[#This Row],[Обьем]]),"") -> 0.91666667 | D35: Добавка | E35: Европа | F35: Масло сливочное традиционное 180 г 82, 5% фольга курскмаслопром - купить онлайн с доставкой по цене 165 в интернет-магазине ЕВРОПА (europa-market.ru) | G35: 180 | H35: 165 | I35: Да
A36: Яйцо | B36: Добавки | C36: =IFERROR(IF(Ингредиенты[[#This Row],[Выход]]<>"",(Ингредиенты[[#This Row],[Цена/Обьем]]/Ингредиенты[[#This Row],[Обьем]]*100%/Ингредиенты[[#This Row],[Выход]]),Ингредиенты[[#This Row],[Цена/Обьем]]/Ингредиенты[[#This Row],[Обьем]]),"") -> 0.11111111 | D36: Добавка | E36: Европа | G36: 1800 | H36: 200 | I36: Да
A37: Вода | B37: Добавки | C37: =IFERROR(IF(Ингредиенты[[#This Row],[Выход]]<>"",(Ингредиенты[[#This Row],[Цена/Обьем]]/Ингредиенты[[#This Row],[Обьем]]*100%/Ингредиенты[[#This Row],[Выход]]),Ингредиенты[[#This Row],[Цена/Обьем]]/Ингредиенты[[#This Row],[Обьем]]),"") -> 0.001 | D37: Добавка | E37: Сам делаю | G37: 1000 | H37: 1 | I37: Да
A38: Мука пшеничная | B38: Добавки | C38: =IFERROR(IF(Ингредиенты[[#This Row],[Выход]]<>"",(Ингредиенты[[#This Row],[Цена/Обьем]]/Ингредиенты[[#This Row],[Обьем]]*100%/Ингредиенты[[#This Row],[Выход]]),Ингредиенты[[#This Row],[Цена/Обьем]]/Ингредиенты[[#This Row],[Обьем]]),"") -> 0.0484 | D38: Добавка | E38: Европа | F38: Мука пшеничная Европа хлебопекарная высший сорт 1кг - купить онлайн с доставкой по цене 48.4 в интернет-магазине ЕВРОПА (europa-market.ru) | G38: 1000 | H38: 48.4 | I38: Да
A39: Уксус 9% | B39: Добавки | C39: =IFERROR(IF(Ингредиенты[[#This Row],[Выход]]<>"",(Ингредиенты[[#This Row],[Цена/Обьем]]/Ингредиенты[[#This Row],[Обьем]]*100%/Ингредиенты[[#This Row],[Выход]]),Ингредиенты[[#This Row],[Цена/Обьем]]/Ингредиенты[[#This Row],[Обьем]]),"") -> 0.173 | D39: Добавка | E39: Озон | F39: Уксус столовый 9% 1 л - купить с доставкой по выгодным ценам в интернет-магазине OZON (1194373193) | G39: 1000 | H39: 173 | I39: Да
A40: Лимонная кислота | B40: Добавки | C40: =IFERROR(IF(Ингредиенты[[#This Row],[Выход]]<>"",(Ингредиенты[[#This Row],[Цена/Обьем]]/Ингредиенты[[#This Row],[Обьем]]*100%/Ингредиенты[[#This Row],[Выход]]),Ингредиенты[[#This Row],[Цена/Обьем]]/Ингредиенты[[#This Row],[Обьем]]),"") -> 0.17766667 | D40: Добавка | E40: Озон | F40: Лимонная кислота пищевая 3 кг - регулятор кислотности, антиокислитель - купить с доставкой по выгодным ценам в интернет-магазине OZON (787154197) | G40: 3000 | H40: 533 | I40: Да
...

Sheet Рецепты
A11: Название | B11: Вид | C11: Способ | D11: Состав | E11: Тип | F11: % | G11: г | H11: р | I11: Масса | J11: Вес ингр-тов | K11: Траты всего | L11: Потери, % | M11: Маржа | N11: Цена за 1 кг | O11: ЧП | P11: Ссылка интернет | Q11: Ссылка ПК | R11: Наличие | S11: Примечание
A12: Докторская | B12: Колбаса | C12: Вареное | D12: Говядина | E12: =VLOOKUP(Рецепты[[#This Row],[Состав]],Ингредиенты[],2,0) -> Говядина | F12: 0.25 | G12: =IF(Рецепты[[#This Row],[%]]*1000>0,Рецепты[[#This Row],[%]]*1000,"") -> 250 | H12: =IFERROR(VLOOKUP(Рецепты[[#This Row],[Состав]],Ингредиенты!A:I,3,0)*Рецепты[[#This Row],[г]],"") -> 177.4975 | I12: =СводРецепт!$A$1 -> 1000 | J12: =Рецепты[[#This Row],[%]]*Рецепты[[#This Row],[Масса]] -> 250 | K12: =Рецепты[[#This Row],[Вес ингр-тов]]*VLOOKUP(Рецепты[[#This Row],[Состав]],Ингредиенты[],3,FALSE) -> 177.4975 | L12: =IF(VLOOKUP(Рецепты[[#This Row],[Состав]],Ингредиенты[],4,0)="Основа",VLOOKUP(Рецепты[[#This Row],[Способ]],Способ[],2,0),0%) -> 0.15 | M12: =VLOOKUP(Рецепты[[#This Row],[Способ]],Способ[],3,0) -> 0.7 | N12: =Рецепты[[#This Row],[р]]*100%/(100%-Рецепты[[#This Row],[Потери, %]])+Рецепты[[#This Row],[Маржа]]*(Рецепты[[#This Row],[р]]*100%)/(100%-Рецепты[[#This Row],[Потери, %]]) -> 354.995 | O12: =Рецепты[[#This Row],[Цена за 1 кг]]-(Рецепты[[#This Row],[р]]*100%/(100%-Рецепты[[#This Row],[Потери, %]])) -> 146.17441 | P12: https://www.youtube.com/watch?v=5gWsIsh4dpM | Q12: D:\Video\Колбаса_рецепты\Докторская колбаса ГОСТ 23670-79 в домашних условиях.mp12 | R12: =VLOOKUP(Рецепты[[#This Row],[Состав]],Ингредиенты[],9,0) -> Да
A13: Докторская | B13: =B12 -> Колбаса | C13: =C12 -> Вареное | D13: Лопатка свиная | E13: =VLOOKUP(Рецепты[[#This Row],[Состав]],Ингредиенты[],2,0) -> Свинина | F13: 0.7 | G13: =IF(Рецепты[[#This Row],[%]]*1000>0,Рецепты[[#This Row],[%]]*1000,"") -> 700 | H13: =IFERROR(VLOOKUP(Рецепты[[#This Row],[Состав]],Ингредиенты!A:I,3,0)*Рецепты[[#This Row],[г]],"") -> 258.3 | I13: =СводРецепт!$A$1 -> 1000 | J13: =Рецепты[[#This Row],[%]]*Рецепты[[#This Row],[Масса]] -> 700 | K13: =Рецепты[[#This Row],[Вес ингр-тов]]*VLOOKUP(Рецепты[[#This Row],[Состав]],Ингредиенты[],3,FALSE) -> 258.3 | L13: =IF(VLOOKUP(Рецепты[[#This Row],[Состав]],Ингредиенты[],4,0)="Основа",VLOOKUP(Рецепты[[#This Row],[Способ]],Способ[],2,0),0%) -> 0.15 | M13: =VLOOKUP(Рецепты[[#This Row],[Способ]],Способ[],3,0) -> 0.7 | N13: =Рецепты[[#This Row],[р]]*100%/(100%-Рецепты[[#This Row],[Потери, %]])+Рецепты[[#This Row],[Маржа]]*(Рецепты[[#This Row],[р]]*100%)/(100%-Рецепты[[#This Row],[Потери, %]]) -> 516.6 | O13: =Рецепты[[#This Row],[Цена за 1 кг]]-(Рецепты[[#This Row],[р]]*100%/(100%-Рецепты[[#This Row],[Потери, %]])) -> 212.71765 | P13: https://www.youtube.com/watch?v=5gWsIsh4dpM | Q13: D:\Video\Колбаса_рецепты\Докторская колбаса ГОСТ 23670-79 в домашних условиях.mp13 | R13: =VLOOKUP(Рецепты[[#This Row],[Состав]],Ингредиенты[],9,0) -> Нет
A14: Докторская | B14: =B13 -> Колбаса | C14: =C13 -> Вареное | D14: Яйцо | E14: =VLOOKUP(Рецепты[[#This Row],[Состав]],Ингредиенты[],2,0) -> Добавки | F14: 0.03 | G14: =IF(Рецепты[[#This Row],[%]]*1000>0,Рецепты[[#This Row],[%]]*1000,"") -> 30 | H14: =IFERROR(VLOOKUP(Рецепты[[#This Row],[Состав]],Ингредиенты!A:I,3,0)*Рецепты[[#This Row],[г]],"") -> 3.3333333 | I14: =СводРецепт!$A$1 -> 1000 | J14: =Рецепты[[#This Row],[%]]*Рецепты[[#This Row],[Масса]] -> 30 | K14: =Рецепты[[#This Row],[Вес ингр-тов]]*VLOOKUP(Рецепты[[#This Row],[Состав]],Ингредиенты[],3,FALSE) -> 3.3333333 | L14: =IF(VLOOKUP(Рецепты[[#This Row],[Состав]],Ингредиенты[],4,0)="Основа",VLOOKUP(Рецепты[[#This Row],[Способ]],Способ[],2,0),0%) -> 0 | M14: =VLOOKUP(Рецепты[[#This Row],[Способ]],Способ[],3,0) -> 0.7 | N14: =Рецепты[[#This Row],[р]]*100%/(100%-Рецепты[[#This Row],[Потери, %]])+Рецепты[[#This Row],[Маржа]]*(Рецепты[[#This Row],[р]]*100%)/(100%-Рецепты[[#This Row],[Потери, %]]) -> 5.6666667 | O14: =Рецепты[[#This Row],[Цена за 1 кг]]-(Рецепты[[#This Row],[р]]*100%/(100%-Рецепты[[#This Row],[Потери, %]])) -> 2.3333333 | P14: https://www.youtube.com/watch?v=5gWsIsh4dpM | Q14: D:\Video\Колбаса_рецепты\Докторская колбаса ГОСТ 23670-79 в домашних условиях.mp14 | R14: =VLOOKUP(Рецепты[[#This Row],[Состав]],Ингредиенты[],9,0) -> Да
A15: Докторская | B15: =B14 -> Колбаса | C15: =C14 -> Вареное | D15: Сухое молоко | E15: =VLOOKUP(Рецепты[[#This Row],[Состав]],Ингредиенты[],2,0) -> Добавки | F15: 0.02 | G15: =IF(Рецепты[[#This Row],[%]]*1000>0,Рецепты[[#This Row],[%]]*1000,"") -> 20 | H15: =IFERROR(VLOOKUP(Рецепты[[#This Row],[Состав]],Ингредиенты!A:I,3,0)*Рецепты[[#This Row],[г]],"") -> 10.98 | I15: =СводРецепт!$A$1 -> 1000 | J15: =Рецепты[[#This Row],[%]]*Рецепты[[#This Row],[Масса]] -> 20 | K15: =Рецепты[[#This Row],[Вес ингр-тов]]*VLOOKUP(Рецепты[[#This Row],[Состав]],Ингредиенты[],3,FALSE) -> 10.98 | L15: =IF(VLOOKUP(Рецепты[[#This Row],[Состав]],Ингредиенты[],4,0)="Основа",VLOOKUP(Рецепты[[#This Row],[Способ]],Способ[],2,0),0%) -> 0 | M15: =VLOOKUP(Рецепты[[#This Row],[Способ]],Способ[],3,0) -> 0.7 | N15: =Рецепты[[#This Row],[р]]*100%/(100%-Рецепты[[#This Row],[Потери, %]])+Рецепты[[#This Row],[Маржа]]*(Рецепты[[#This Row],[р]]*100%)/(100%-Рецепты[[#This Row],[Потери, %]]) -> 18.666 | O15: =Рецепты[[#This Row],[Цена за 1 кг]]-(Рецепты[[#This Row],[р]]*100%/(100%-Рецепты[[#This Row],[Потери, %]])) -> 7.686 | P15: https://www.youtube.com/watch?v=5gWsIsh4dpM | Q15: D:\Video\Колбаса_рецепты\Докторская колбаса ГОСТ 23670-79 в домашних условиях.mp15 | R15: =VLOOKUP(Рецепты[[#This Row],[Состав]],Ингредиенты[],9,0) -> Да
A16: Докторская | B16: Колбаса | C16: Вареное | D16: Соль нитритная | E16: =VLOOKUP(Рецепты[[#This Row],[Состав]],Ингредиенты[],2,0) -> Специи | F16: 0.02 | G16: =IF(Рецепты[[#This Row],[%]]*1000>0,Рецепты[[#This Row],[%]]*1000,"") -> 20 | H16: =IFERROR(VLOOKUP(Рецепты[[#This Row],[Состав]],Ингредиенты!A:I,3,0)*Рецепты[[#This Row],[г]],"") -> 2.56 | I16: =СводРецепт!$A$1 -> 1000 | J16: =Рецепты[[#This Row],[%]]*Рецепты[[#This Row],[Масса]] -> 20 | K16: =Рецепты[[#This Row],[Вес ингр-тов]]*VLOOKUP(Рецепты[[#This Row],[Состав]],Ингредиенты[],3,FALSE) -> 2.56 | L16: =IF(VLOOKUP(Рецепты[[#This Row],[Состав]],Ингредиенты[],4,0)="Основа",VLOOKUP(Рецепты[[#This Row],[Способ]],Способ[],2,0),0%) -> 0 | M16: =VLOOKUP(Рецепты[[#This Row],[Способ]],Способ[],3,0) -> 0.7 | N16: =Рецепты[[#This Row],[р]]*100%/(100%-Рецепты[[#This Row],[Потери, %]])+Рецепты[[#This Row],[Маржа]]*(Рецепты[[#This Row],[р]]*100%)/(100%-Рецепты[[#This Row],[Потери, %]]) -> 4.352 | O16: =Рецепты[[#This Row],[Цена за 1 кг]]-(Рецепты[[#This Row],[р]]*100%/(100%-Рецепты[[#This Row],[Потери, %]])) -> 1.792 | P16: https://www.youtube.com/watch?v=5gWsIsh4dpM | Q16: D:\Video\Колбаса_рецепты\Докторская колбаса ГОСТ 23670-79 в домашних условиях.mp17 | R16: =VLOOKUP(Рецепты[[#This Row],[Состав]],Ингредиенты[],9,0) -> Да
A17: Докторская | B17: =B16 -> Колбаса | C17: =C16 -> Вареное | D17: Вода | E17: =VLOOKUP(Рецепты[[#This Row],[Состав]],Ингредиенты[],2,0) -> Добавки | F17: 0.1 | G17: =IF(Рецепты[[#This Row],[%]]*1000>0,Рецепты[[#This Row],[%]]*1000,"") -> 100 | H17: =IFERROR(VLOOKUP(Рецепты[[#This Row],[Состав]],Ингредиенты!A:I,3,0)*Рецепты[[#This Row],[г]],"") -> 0.1 | I17: =СводРецепт!$A$1 -> 1000 | J17: =Рецепты[[#This Row],[%]]*Рецепты[[#This Row],[Масса]] -> 100 | K17: =Рецепты[[#This Row],[Вес ингр-тов]]*VLOOKUP(Рецепты[[#This Row],[Состав]],Ингредиенты[],3,FALSE) -> 0.1 | L17: =IF(VLOOKUP(Рецепты[[#This Row],[Состав]],Ингредиенты[],4,0)="Основа",VLOOKUP(Рецепты[[#This Row],[Способ]],Способ[],2,0),0%) -> 0 | M17: =VLOOKUP(Рецепты[[#This Row],[Способ]],Способ[],3,0) -> 0.7 | N17: =Рецепты[[#This Row],[р]]*100%/(100%-Рецепты[[#This Row],[Потери, %]])+Рецепты[[#This Row],[Маржа]]*(Рецепты[[#This Row],[р]]*100%)/(100%-Рецепты[[#This Row],[Потери, %]]) -> 0.17 | O17: =Рецепты[[#This Row],[Цена за 1 кг]]-(Рецепты[[#This Row],[р]]*100%/(100%-Рецепты[[#This Row],[Потери, %]])) -> 0.07 | P17: https://www.youtube.com/watch?v=5gWsIsh4dpM | Q17: D:\Video\Колбаса_рецепты\Докторская колбаса ГОСТ 23670-79 в домашних условиях.mp18 | R17: =VLOOKUP(Рецепты[[#This Row],[Состав]],Ингредиенты[],9,0) -> Да
A18: Докторская | B18: =B17 -> Колбаса | C18: =C17 -> Вареное | D18: Фосфат | E18: =VLOOKUP(Рецепты[[#This Row],[Состав]],Ингредиенты[],2,0) -> Специи | F18: 0.002 | G18: =IF(Рецепты[[#This Row],[%]]*1000>0,Рецепты[[#This Row],[%]]*1000,"") -> 2 | H18: =IFERROR(VLOOKUP(Рецепты[[#This Row],[Состав]],Ингредиенты!A:I,3,0)*Рецепты[[#This Row],[г]],"") -> 1.496 | I18: =СводРецепт!$A$1 -> 1000 | J18: =Рецепты[[#This Row],[%]]*Рецепты[[#This Row],[Масса]] -> 2 | K18: =Рецепты[[#This Row],[Вес ингр-тов]]*VLOOKUP(Рецепты[[#This Row],[Состав]],Ингредиенты[],3,FALSE) -> 1.496 | L18: =IF(VLOOKUP(Рецепты[[#This Row],[Состав]],Ингредиенты[],4,0)="Основа",VLOOKUP(Рецепты[[#This Row],[Способ]],Способ[],2,0),0%) -> 0 | M18: =VLOOKUP(Рецепты[[#This Row],[Способ]],Способ[],3,0) -> 0.7 | N18: =Рецепты[[#This Row],[р]]*100%/(100%-Рецепты[[#This Row],[Потери, %]])+Рецепты[[#This Row],[Маржа]]*(Рецепты[[#This Row],[р]]*100%)/(100%-Рецепты[[#This Row],[Потери, %]]) -> 2.5432 | O18: =Рецепты[[#This Row],[Цена за 1 кг]]-(Рецепты[[#This Row],[р]]*100%/(100%-Рецепты[[#This Row],[Потери, %]])) -> 1.0472 | P18: https://www.youtube.com/watch?v=5gWsIsh4dpM | Q18: D:\Video\Колбаса_рецепты\Докторская колбаса ГОСТ 23670-79 в домашних условиях.mp19 | R18: =VLOOKUP(Рецепты[[#This Row],[Состав]],Ингредиенты[],9,0) -> Да
A19: Докторская | B19: =B17 -> Колбаса | C19: =C17 -> Вареное | D19: Кардамон | E19: =VLOOKUP(Рецепты[[#This Row],[Состав]],Ингредиенты[],2,0) -> Специи | F19: 0.0005 | G19: =IF(Рецепты[[#This Row],[%]]*1000>0,Рецепты[[#This Row],[%]]*1000,"") -> 0.5 | H19: =IFERROR(VLOOKUP(Рецепты[[#This Row],[Состав]],Ингредиенты!A:I,3,0)*Рецепты[[#This Row],[г]],"") -> 0.75666667 | I19: =СводРецепт!$A$1 -> 1000 | J19: =Рецепты[[#This Row],[%]]*Рецепты[[#This Row],[Масса]] -> 0.5 | K19: =Рецепты[[#This Row],[Вес ингр-тов]]*VLOOKUP(Рецепты[[#This Row],[Состав]],Ингредиенты[],3,FALSE) -> 0.75666667 | L19: =IF(VLOOKUP(Рецепты[[#This Row],[Состав]],Ингредиенты[],4,0)="Основа",VLOOKUP(Рецепты[[#This Row],[Способ]],Способ[],2,0),0%) -> 0 | M19: =VLOOKUP(Рецепты[[#This Row],[Способ]],Способ[],3,0) -> 0.7 | N19: =Рецепты[[#This Row],[р]]*100%/(100%-Рецепты[[#This Row],[Потери, %]])+Рецепты[[#This Row],[Маржа]]*(Рецепты[[#This Row],[р]]*100%)/(100%-Рецепты[[#This Row],[Потери, %]]) -> 1.2863333 | O19: =Рецепты[[#This Row],[Цена за 1 кг]]-(Рецепты[[#This Row],[р]]*100%/(100%-Рецепты[[#This Row],[Потери, %]])) -> 0.52966667 | P19: https://www.youtube.com/watch?v=5gWsIsh4dpM | Q19: D:\Video\Колбаса_рецепты\Докторская колбаса ГОСТ 23670-79 в домашних условиях.mp19 | R19: =VLOOKUP(Рецепты[[#This Row],[Состав]],Ингредиенты[],9,0) -> Да
A20: Докторская | B20: =B19 -> Колбаса | C20: =C19 -> Вареное | D20: Полиамидная 80 | E20: =VLOOKUP(Рецепты[[#This Row],[Состав]],Ингредиенты[],2,0) -> Оболочка | F20: 0.001 | G20: =IF(Рецепты[[#This Row],[%]]*1000>0,Рецепты[[#This Row],[%]]*1000,"") -> 1 | H20: =IFERROR(VLOOKUP(Рецепты[[#This Row],[Состав]],Ингредиенты!A:I,3,0)*Рецепты[[#This Row],[г]],"") -> 9.7374533 | I20: =СводРецепт!$A$1 -> 1000 | J20: =Рецепты[[#This Row],[%]]*Рецепты[[#This Row],[Масса]] -> 1 | K20: =Рецепты[[#This Row],[Вес ингр-тов]]*VLOOKUP(Рецепты[[#This Row],[Состав]],Ингредиенты[],3,FALSE) -> 9.7374533 | L20: =IF(VLOOKUP(Рецепты[[#This Row],[Состав]],Ингредиенты[],4,0)="Основа",VLOOKUP(Рецепты[[#This Row],[Способ]],Способ[],2,0),0%) -> 0 | M20: =VLOOKUP(Рецепты[[#This Row],[Способ]],Способ[],3,0) -> 0.7 | N20: =Рецепты[[#This Row],[р]]*100%/(100%-Рецепты[[#This Row],[Потери, %]])+Рецепты[[#This Row],[Маржа]]*(Рецепты[[#This Row],[р]]*100%)/(100%-Рецепты[[#This Row],[Потери, %]]) -> 16.553671 | O20: =Рецепты[[#This Row],[Цена за 1 кг]]-(Рецепты[[#This Row],[р]]*100%/(100%-Рецепты[[#This Row],[Потери, %]])) -> 6.8162173 | P20: https://www.youtube.com/watch?v=5gWsIsh4dpM | Q20: D:\Video\Колбаса_рецепты\Докторская колбаса ГОСТ 23670-79 в домашних условиях.mp20 | R20: =VLOOKUP(Рецепты[[#This Row],[Состав]],Ингредиенты[],9,0) -> Да
A21: Куриные Сырные | B21: Сосиски | C21: =C19 -> Вареное | D21: Грудка куриная | E21: =VLOOKUP(Рецепты[[#This Row],[Состав]],Ингредиенты[],2,0) -> Птица | F21: 0.2 | G21: =IF(Рецепты[[#This Row],[%]]*1000>0,Рецепты[[#This Row],[%]]*1000,"") -> 200 | H21: =IFERROR(VLOOKUP(Рецепты[[#This Row],[Состав]],Ингредиенты!A:I,3,0)*Рецепты[[#This Row],[г]],"") -> 55.998 | I21: =СводРецепт!$A$1 -> 1000 | J21: =Рецепты[[#This Row],[%]]*Рецепты[[#This Row],[Масса]] -> 200 | K21: =Рецепты[[#This Row],[Вес ингр-тов]]*VLOOKUP(Рецепты[[#This Row],[Состав]],Ингредиенты[],3,FALSE) -> 55.998 | L21: =IF(VLOOKUP(Рецепты[[#This Row],[Состав]],Ингредиенты[],4,0)="Основа",VLOOKUP(Рецепты[[#This Row],[Способ]],Способ[],2,0),0%) -> 0.15 | M21: =VLOOKUP(Рецепты[[#This Row],[Способ]],Способ[],3,0) -> 0.7 | N21: =Рецепты[[#This Row],[р]]*100%/(100%-Рецепты[[#This Row],[Потери, %]])+Рецепты[[#This Row],[Маржа]]*(Рецепты[[#This Row],[р]]*100%)/(100%-Рецепты[[#This Row],[Потери, %]]) -> 111.996 | O21: =Рецепты[[#This Row],[Цена за 1 кг]]-(Рецепты[[#This Row],[р]]*100%/(100%-Рецепты[[#This Row],[Потери, %]])) -> 46.116 | P21: https://www.youtube.com/watch?v=WJ2KT_frzos&t=16s | Q21: D:\Video\Колбаса_рецепты\Домашние куриные сосиски с твердым сыром.mp4 | R21: =VLOOKUP(Рецепты[[#This Row],[Состав]],Ингредиенты[],9,0) -> Нет
A22: Куриные Сырные | B22: =B21 -> Сосиски | C22: =C21 -> Вареное | D22: Бедра куриные | E22: =VLOOKUP(Рецепты[[#This Row],[Состав]],Ингредиенты[],2,0) -> Птица | F22: 0.6 | G22: =IF(Рецепты[[#This Row],[%]]*1000>0,Рецепты[[#This Row],[%]]*1000,"") -> 600 | H22: =IFERROR(VLOOKUP(Рецепты[[#This Row],[Состав]],Ингредиенты!A:I,3,0)*Рецепты[[#This Row],[г]],"") -> 156.70588 | I22: =СводРецепт!$A$1 -> 1000 | J22: =Рецепты[[#This Row],[%]]*Рецепты[[#This Row],[Масса]] -> 600 | K22: =Рецепты[[#This Row],[Вес ингр-тов]]*VLOOKUP(Рецепты[[#This Row],[Состав]],Ингредиенты[],3,FALSE) -> 156.70588 | L22: =IF(VLOOKUP(Рецепты[[#This Row],[Состав]],Ингредиенты[],4,0)="Основа",VLOOKUP(Рецепты[[#This Row],[Способ]],Способ[],2,0),0%) -> 0.15 | M22: =VLOOKUP(Рецепты[[#This Row],[Способ]],Способ[],3,0) -> 0.7 | N22: =Рецепты[[#This Row],[р]]*100%/(100%-Рецепты[[#This Row],[Потери, %]])+Рецепты[[#This Row],[Маржа]]*(Рецепты[[#This Row],[р]]*100%)/(100%-Рецепты[[#This Row],[Потери, %]]) -> 313.41176 | O22: =Рецепты[[#This Row],[Цена за 1 кг]]-(Рецепты[[#This Row],[р]]*100%/(100%-Рецепты[[#This Row],[Потери, %]])) -> 129.0519 | P22: https://www.youtube.com/watch?v=WJ2KT_frzos&t=16s | Q22: D:\Video\Колбаса_рецепты\Домашние куриные сосиски с твердым сыром.mp5 | R22: =VLOOKUP(Рецепты[[#This Row],[Состав]],Ингредиенты[],9,0) -> Нет
A23: Куриные Сырные | B23: =B22 -> Сосиски | C23: =C22 -> Вареное | D23: Сыр российский | E23: =VLOOKUP(Рецепты[[#This Row],[Состав]],Ингредиенты[],2,0) -> Добавки | F23: 0.2 | G23: =IF(Рецепты[[#This Row],[%]]*1000>0,Рецепты[[#This Row],[%]]*1000,"") -> 200 | H23: =IFERROR(VLOOKUP(Рецепты[[#This Row],[Состав]],Ингредиенты!A:I,3,0)*Рецепты[[#This Row],[г]],"") -> 159.998 | I23: =СводРецепт!$A$1 -> 1000 | J23: =Рецепты[[#This Row],[%]]*Рецепты[[#This Row],[Масса]] -> 200 | K23: =Рецепты[[#This Row],[Вес ингр-тов]]*VLOOKUP(Рецепты[[#This Row],[Состав]],Ингредиенты[],3,FALSE) -> 159.998 | L23: =IF(VLOOKUP(Рецепты[[#This Row],[Состав]],Ингредиенты[],4,0)="Основа",VLOOKUP(Рецепты[[#This Row],[Способ]],Способ[],2,0),0%) -> 0 | M23: =VLOOKUP(Рецепты[[#This Row],[Способ]],Способ[],3,0) -> 0.7 | N23: =Рецепты[[#This Row],[р]]*100%/(100%-Рецепты[[#This Row],[Потери, %]])+Рецепты[[#This Row],[Маржа]]*(Рецепты[[#This Row],[р]]*100%)/(100%-Рецепты[[#This Row],[Потери, %]]) -> 271.9966 | O23: =Рецепты[[#This Row],[Цена за 1 кг]]-(Рецепты[[#This Row],[р]]*100%/(100%-Рецепты[[#This Row],[Потери, %]])) -> 111.9986 | P23: https://www.youtube.com/watch?v=WJ2KT_frzos&t=16s | Q23: D:\Video\Колбаса_рецепты\Домашние куриные сосиски с твердым сыром.mp6 | R23: =VLOOKUP(Рецепты[[#This Row],[Состав]],Ингредиенты[],9,0) -> Нет
A24: Куриные Сырные | B24: =B23 -> Сосиски | C24: =C23 -> Вареное | D24: Соль пищевая | E24: =VLOOKUP(Рецепты[[#This Row],[Состав]],Ингредиенты[],2,0) -> Специи | F24: 0.008 | G24: =IF(Рецепты[[#This Row],[%]]*1000>0,Рецепты[[#This Row],[%]]*1000,"") -> 8 | H24: =IFERROR(VLOOKUP(Рецепты[[#This Row],[Состав]],Ингредиенты!A:I,3,0)*Рецепты[[#This Row],[г]],"") -> 0.308 | I24: =СводРецепт!$A$1 -> 1000 | J24: =Рецепты[[#This Row],[%]]*Рецепты[[#This Row],[Масса]] -> 8 | K24: =Рецепты[[#This Row],[Вес ингр-тов]]*VLOOKUP(Рецепты[[#This Row],[Состав]],Ингредиенты[],3,FALSE) -> 0.308 | L24: =IF(VLOOKUP(Рецепты[[#This Row],[Состав]],Ингредиенты[],4,0)="Основа",VLOOKUP(Рецепты[[#This Row],[Способ]],Способ[],2,0),0%) -> 0 | M24: =VLOOKUP(Рецепты[[#This Row],[Способ]],Способ[],3,0) -> 0.7 | N24: =Рецепты[[#This Row],[р]]*100%/(100%-Рецепты[[#This Row],[Потери, %]])+Рецепты[[#This Row],[Маржа]]*(Рецепты[[#This Row],[р]]*100%)/(100%-Рецепты[[#This Row],[Потери, %]]) -> 0.5236 | O24: =Рецепты[[#This Row],[Цена за 1 кг]]-(Рецепты[[#This Row],[р]]*100%/(100%-Рецепты[[#This Row],[Потери, %]])) -> 0.2156 | P24: https://www.youtube.com/watch?v=WJ2KT_frzos&t=16s | Q24: D:\Video\Колбаса_рецепты\Домашние куриные сосиски с твердым сыром.mp7 | R24: =VLOOKUP(Рецепты[[#This Row],[Состав]],Ингредиенты[],9,0) -> Да
A25: Куриные Сырные | B25: =B24 -> Сосиски | C25: =C24 -> Вареное | D25: Соль нитритная | E25: =VLOOKUP(Рецепты[[#This Row],[Состав]],Ингредиенты[],2,0) -> Специи | F25: 0.008 | G25: =IF(Рецепты[[#This Row],[%]]*1000>0,Рецепты[[#This Row],[%]]*1000,"") -> 8 | H25: =IFERROR(VLOOKUP(Рецепты[[#This Row],[Состав]],Ингредиенты!A:I,3,0)*Рецепты[[#This Row],[г]],"") -> 1.024 | I25: =СводРецепт!$A$1 -> 1000 | J25: =Рецепты[[#This Row],[%]]*Рецепты[[#This Row],[Масса]] -> 8 | K25: =Рецепты[[#This Row],[Вес ингр-тов]]*VLOOKUP(Рецепты[[#This Row],[Состав]],Ингредиенты[],3,FALSE) -> 1.024 | L25: =IF(VLOOKUP(Рецепты[[#This Row],[Состав]],Ингредиенты[],4,0)="Основа",VLOOKUP(Рецепты[[#This Row],[Способ]],Способ[],2,0),0%) -> 0 | M25: =VLOOKUP(Рецепты[[#This Row],[Способ]],Способ[],3,0) -> 0.7 | N25: =Рецепты[[#This Row],[р]]*100%/(100%-Рецепты[[#This Row],[Потери, %]])+Рецепты[[#This Row],[Маржа]]*(Рецепты[[#This Row],[р]]*100%)/(100%-Рецепты[[#This Row],[Потери, %]]) -> 1.7408 | O25: =Рецепты[[#This Row],[Цена за 1 кг]]-(Рецепты[[#This Row],[р]]*100%/(100%-Рецепты[[#This Row],[Потери, %]])) -> 0.7168 | P25: https://www.youtube.com/watch?v=WJ2KT_frzos&t=16s | Q25: D:\Video\Колбаса_рецепты\Домашние куриные сосиски с твердым сыром.mp8 | R25: =VLOOKUP(Рецепты[[#This Row],[Состав]],Ингредиенты[],9,0) -> Да
A26: Куриные Сырные | B26: =B25 -> Сосиски | C26: =C25 -> Вареное | D26: Сахар | E26: =VLOOKUP(Рецепты[[#This Row],[Состав]],Ингредиенты[],2,0) -> Специи | F26: 0.001 | G26: =IF(Рецепты[[#This Row],[%]]*1000>0,Рецепты[[#This Row],[%]]*1000,"") -> 1 | H26: =IFERROR(VLOOKUP(Рецепты[[#This Row],[Состав]],Ингредиенты!A:I,3,0)*Рецепты[[#This Row],[г]],"") -> 0.080882353 | I26: =СводРецепт!$A$1 -> 1000 | J26: =Рецепты[[#This Row],[%]]*Рецепты[[#This Row],[Масса]] -> 1 | K26: =Рецепты[[#This Row],[Вес ингр-тов]]*VLOOKUP(Рецепты[[#This Row],[Состав]],Ингредиенты[],3,FALSE) -> 0.080882353 | L26: =IF(VLOOKUP(Рецепты[[#This Row],[Состав]],Ингредиенты[],4,0)="Основа",VLOOKUP(Рецепты[[#This Row],[Способ]],Способ[],2,0),0%) -> 0 | M26: =VLOOKUP(Рецепты[[#This Row],[Способ]],Способ[],3,0) -> 0.7 | N26: =Рецепты[[#This Row],[р]]*100%/(100%-Рецепты[[#This Row],[Потери, %]])+Рецепты[[#This Row],[Маржа]]*(Рецепты[[#This Row],[р]]*100%)/(100%-Рецепты[[#This Row],[Потери, %]]) -> 0.1375 | O26: =Рецепты[[#This Row],[Цена за 1 кг]]-(Рецепты[[#This Row],[р]]*100%/(100%-Рецепты[[#This Row],[Потери, %]])) -> 0.056617647 | P26: https://www.youtube.com/watch?v=WJ2KT_frzos&t=16s | Q26: D:\Video\Колбаса_рецепты\Домашние куриные сосиски с твердым сыром.mp9 | R26: =VLOOKUP(Рецепты[[#This Row],[Состав]],Ингредиенты[],9,0) -> Да
A27: Куриные Сырные | B27: =B26 -> Сосиски | C27: =C26 -> Вареное | D27: Перец черный молотый | E27: =VLOOKUP(Рецепты[[#This Row],[Состав]],Ингредиенты[],2,0) -> Специи | F27: 0.001 | G27: =IF(Рецепты[[#This Row],[%]]*1000>0,Рецепты[[#This Row],[%]]*1000,"") -> 1 | H27: =IFERROR(VLOOKUP(Рецепты[[#This Row],[Состав]],Ингредиенты!A:I,3,0)*Рецепты[[#This Row],[г]],"") -> 1.0945455 | I27: =СводРецепт!$A$1 -> 1000 | J27: =Рецепты[[#This Row],[%]]*Рецепты[[#This Row],[Масса]] -> 1 | K27: =Рецепты[[#This Row],[Вес ингр-тов]]*VLOOKUP(Рецепты[[#This Row],[Состав]],Ингредиенты[],3,FALSE) -> 1.0945455 | L27: =IF(VLOOKUP(Рецепты[[#This Row],[Состав]],Ингредиенты[],4,0)="Основа",VLOOKUP(Рецепты[[#This Row],[Способ]],Способ[],2,0),0%) -> 0 | M27: =VLOOKUP(Рецепты[[#This Row],[Способ]],Способ[],3,0) -> 0.7 | N27: =Рецепты[[#This Row],[р]]*100%/(100%-Рецепты[[#This Row],[Потери, %]])+Рецепты[[#This Row],[Маржа]]*(Рецепты[[#This Row],[р]]*100%)/(100%-Рецепты[[#This Row],[Потери, %]]) -> 1.8607273 | O27: =Рецепты[[#This Row],[Цена за 1 кг]]-(Рецепты[[#This Row],[р]]*100%/(100%-Рецепты[[#This Row],[Потери, %]])) -> 0.76618182 | P27: https://www.youtube.com/watch?v=WJ2KT_frzos&t=16s | Q27: D:\Video\Колбаса_рецепты\Домашние куриные сосиски с твердым сыром.mp10 | R27: =VLOOKUP(Рецепты[[#This Row],[Состав]],Ингредиенты[],9,0) -> Да
A28: Куриные Сырные | B28: =B27 -> Сосиски | C28: =C27 -> Вареное | D28: Мускатный орех | E28: =VLOOKUP(Рецепты[[#This Row],[Состав]],Ингредиенты[],2,0) -> Специи | F28: 0.0005 | G28: =IF(Рецепты[[#This Row],[%]]*1000>0,Рецепты[[#This Row],[%]]*1000,"") -> 0.5 | H28: =IFERROR(VLOOKUP(Рецепты[[#This Row],[Состав]],Ингредиенты!A:I,3,0)*Рецепты[[#This Row],[г]],"") -> 1.0386364 | I28: =СводРецепт!$A$1 -> 1000 | J28: =Рецепты[[#This Row],[%]]*Рецепты[[#This Row],[Масса]] -> 0.5 | K28: =Рецепты[[#This Row],[Вес ингр-тов]]*VLOOKUP(Рецепты[[#This Row],[Состав]],Ингредиенты[],3,FALSE) -> 1.0386364 | L28: =IF(VLOOKUP(Рецепты[[#This Row],[Состав]],Ингредиенты[],4,0)="Основа",VLOOKUP(Рецепты[[#This Row],[Способ]],Способ[],2,0),0%) -> 0 | M28: =VLOOKUP(Рецепты[[#This Row],[Способ]],Способ[],3,0) -> 0.7 | N28: =Рецепты[[#This Row],[р]]*100%/(100%-Рецепты[[#This Row],[Потери, %]])+Рецепты[[#This Row],[Маржа]]*(Рецепты[[#This Row],[р]]*100%)/(100%-Рецепты[[#This Row],[Потери, %]]) -> 1.7656818 | O28: =Рецепты[[#This Row],[Цена за 1 кг]]-(Рецепты[[#This Row],[р]]*100%/(100%-Рецепты[[#This Row],[Потери, %]])) -> 0.72704545 | P28: https://www.youtube.com/watch?v=WJ2KT_frzos&t=16s | Q28: D:\Video\Колбаса_рецепты\Домашние куриные сосиски с твердым сыром.mp11 | R28: =VLOOKUP(Рецепты[[#This Row],[Состав]],Ингредиенты[],9,0) -> Да
A29: Куриные Сырные | B29: =B28 -> Сосиски | C29: =C28 -> Вареное | D29: Сливки | E29: =VLOOKUP(Рецепты[[#This Row],[Состав]],Ингредиенты[],2,0) -> Добавки | F29: 0.15 | G29: =IF(Рецепты[[#This Row],[%]]*1000>0,Рецепты[[#This Row],[%]]*1000,"") -> 150 | H29: =IFERROR(VLOOKUP(Рецепты[[#This Row],[Состав]],Ингредиенты!A:I,3,0)*Рецепты[[#This Row],[г]],"") -> 75.9 | I29: =СводРецепт!$A$1 -> 1000 | J29: =Рецепты[[#This Row],[%]]*Рецепты[[#This Row],[Масса]] -> 150 | K29: =Рецепты[[#This Row],[Вес ингр-тов]]*VLOOKUP(Рецепты[[#This Row],[Состав]],Ингредиенты[],3,FALSE) -> 75.9 | L29: =IF(VLOOKUP(Рецепты[[#This Row],[Состав]],Ингредиенты[],4,0)="Основа",VLOOKUP(Рецепты[[#This Row],[Способ]],Способ[],2,0),0%) -> 0 | M29: =VLOOKUP(Рецепты[[#This Row],[Способ]],Способ[],3,0) -> 0.7 | N29: =Рецепты[[#This Row],[р]]*100%/(100%-Рецепты[[#This Row],[Потери, %]])+Рецепты[[#This Row],[Маржа]]*(Рецепты[[#This Row],[р]]*100%)/(100%-Рецепты[[#This Row],[Потери, %]]) -> 129.03 | O29: =Рецепты[[#This Row],[Цена за 1 кг]]-(Рецепты[[#This Row],[р]]*100%/(100%-Рецепты[[#This Row],[Потери, %]])) -> 53.13 | P29: https://www.youtube.com/watch?v=WJ2KT_frzos&t=16s | Q29: D:\Video\Колбаса_рецепты\Домашние куриные сосиски с твердым сыром.mp12 | R29: =VLOOKUP(Рецепты[[#This Row],[Состав]],Ингредиенты[],9,0) -> Да
A30: Куриные Сырные | B30: =B29 -> Сосиски | C30: =C29 -> Вареное | D30: Полиамидная сосисочная | E30: =VLOOKUP(Рецепты[[#This Row],[Состав]],Ингредиенты[],2,0) -> Оболочка | F30: 0.001 | G30: =IF(Рецепты[[#This Row],[%]]*1000>0,Рецепты[[#This Row],[%]]*1000,"") -> 1 | H30: =IFERROR(VLOOKUP(Рецепты[[#This Row],[Состав]],Ингредиенты!A:I,3,0)*Рецепты[[#This Row],[г]],"") -> 15.40718 | I30: =СводРецепт!$A$1 -> 1000 | J30: =Рецепты[[#This Row],[%]]*Рецепты[[#This Row],[Масса]] -> 1 | K30: =Рецепты[[#This Row],[Вес ингр-тов]]*VLOOKUP(Рецепты[[#This Row],[Состав]],Ингредиенты[],3,FALSE) -> 15.40718 | L30: =IF(VLOOKUP(Рецепты[[#This Row],[Состав]],Ингредиенты[],4,0)="Основа",VLOOKUP(Рецепты[[#This Row],[Способ]],Способ[],2,0),0%) -> 0 | M30: =VLOOKUP(Рецепты[[#This Row],[Способ]],Способ[],3,0) -> 0.7 | N30: =Рецепты[[#This Row],[р]]*100%/(100%-Рецепты[[#This Row],[Потери, %]])+Рецепты[[#This Row],[Маржа]]*(Рецепты[[#This Row],[р]]*100%)/(100%-Рецепты[[#This Row],[Потери, %]]) -> 26.192206 | O30: =Рецепты[[#This Row],[Цена за 1 кг]]-(Рецепты[[#This Row],[р]]*100%/(100%-Рецепты[[#This Row],[Потери, %]])) -> 10.785026 | P30: https://www.youtube.com/watch?v=WJ2KT_frzos&t=16s | Q30: D:\Video\Колбаса_рецепты\Домашние куриные сосиски с твердым сыром.mp13 | R30: =VLOOKUP(Рецепты[[#This Row],[Состав]],Ингредиенты[],9,0) -> Да
A31: Сардельки Свиные | B31: =B30 -> Сосиски | C31: =C29 -> Вареное | D31: Лопатка свиная | E31: =VLOOKUP(Рецепты[[#This Row],[Состав]],Ингредиенты[],2,0) -> Свинина | F31: 1 | G31: =IF(Рецепты[[#This Row],[%]]*1000>0,Рецепты[[#This Row],[%]]*1000,"") -> 1000 | H31: =IFERROR(VLOOKUP(Рецепты[[#This Row],[Состав]],Ингредиенты!A:I,3,0)*Рецепты[[#This Row],[г]],"") -> 369 | I31: =СводРецепт!$A$1 -> 1000 | J31: =Рецепты[[#This Row],[%]]*Рецепты[[#This Row],[Масса]] -> 1000 | K31: =Рецепты[[#This Row],[Вес ингр-тов]]*VLOOKUP(Рецепты[[#This Row],[Состав]],Ингредиенты[],3,FALSE) -> 369 | L31: =IF(VLOOKUP(Рецепты[[#This Row],[Состав]],Ингредиенты[],4,0)="Основа",VLOOKUP(Рецепты[[#This Row],[Способ]],Способ[],2,0),0%) -> 0.15 | M31: =VLOOKUP(Рецепты[[#This Row],[Способ]],Способ[],3,0) -> 0.7 | N31: =Рецепты[[#This Row],[р]]*100%/(100%-Рецепты[[#This Row],[Потери, %]])+Рецепты[[#This Row],[Маржа]]*(Рецепты[[#This Row],[р]]*100%)/(100%-Рецепты[[#This Row],[Потери, %]]) -> 738 | O31: =Рецепты[[#This Row],[Цена за 1 кг]]-(Рецепты[[#This Row],[р]]*100%/(100%-Рецепты[[#This Row],[Потери, %]])) -> 303.88235 | P31: https://www.youtube.com/watch?v=Mu_glCpe-Y8 | Q31: D:\Video\Колбаса_рецепты\Сочные домашние сардельки Кнакеры. Как сделать корочку, чтобы сардельки ''хрупали'' при укусе..mp4 | R31: =VLOOKUP(Рецепты[[#This Row],[Состав]],Ингредиенты[],9,0) -> Нет
A32: Сардельки Свиные | B32: =B31 -> Сосиски | C32: =C31 -> Вареное | D32: Вода | E32: =VLOOKUP(Рецепты[[#This Row],[Состав]],Ингредиенты[],2,0) -> Добавки | F32: 0.3 | G32: =IF(Рецепты[[#This Row],[%]]*1000>0,Рецепты[[#This Row],[%]]*1000,"") -> 300 | H32: =IFERROR(VLOOKUP(Рецепты[[#This Row],[Состав]],Ингредиенты!A:I,3,0)*Рецепты[[#This Row],[г]],"") -> 0.3 | I32: =СводРецепт!$A$1 -> 1000 | J32: =Рецепты[[#This Row],[%]]*Рецепты[[#This Row],[Масса]] -> 300 | K32: =Рецепты[[#This Row],[Вес ингр-тов]]*VLOOKUP(Рецепты[[#This Row],[Состав]],Ингредиенты[],3,FALSE) -> 0.3 | L32: =IF(VLOOKUP(Рецепты[[#This Row],[Состав]],Ингредиенты[],4,0)="Основа",VLOOKUP(Рецепты[[#This Row],[Способ]],Способ[],2,0),0%) -> 0 | M32: =VLOOKUP(Рецепты[[#This Row],[Способ]],Способ[],3,0) -> 0.7 | N32: =Рецепты[[#This Row],[р]]*100%/(100%-Рецепты[[#This Row],[Потери, %]])+Рецепты[[#This Row],[Маржа]]*(Рецепты[[#This Row],[р]]*100%)/(100%-Рецепты[[#This Row],[Потери, %]]) -> 0.51 | O32: =Рецепты[[#This Row],[Цена за 1 кг]]-(Рецепты[[#This Row],[р]]*100%/(100%-Рецепты[[#This Row],[Потери, %]])) -> 0.21 | P32: https://www.youtube.com/watch?v=Mu_glCpe-Y8 | Q32: D:\Video\Колбаса_рецепты\Сочные домашние сардельки Кнакеры. Как сделать корочку, чтобы сардельки ''хрупали'' при укусе..mp6 | R32: =VLOOKUP(Рецепты[[#This Row],[Состав]],Ингредиенты[],9,0) -> Да
A33: Сардельки Свиные | B33: =B32 -> Сосиски | C33: =C32 -> Вареное | D33: Соль пищевая | E33: =VLOOKUP(Рецепты[[#This Row],[Состав]],Ингредиенты[],2,0) -> Специи | F33: 0.01 | G33: =IF(Рецепты[[#This Row],[%]]*1000>0,Рецепты[[#This Row],[%]]*1000,"") -> 10 | H33: =IFERROR(VLOOKUP(Рецепты[[#This Row],[Состав]],Ингредиенты!A:I,3,0)*Рецепты[[#This Row],[г]],"") -> 0.385 | I33: =СводРецепт!$A$1 -> 1000 | J33: =Рецепты[[#This Row],[%]]*Рецепты[[#This Row],[Масса]] -> 10 | K33: =Рецепты[[#This Row],[Вес ингр-тов]]*VLOOKUP(Рецепты[[#This Row],[Состав]],Ингредиенты[],3,FALSE) -> 0.385 | L33: =IF(VLOOKUP(Рецепты[[#This Row],[Состав]],Ингредиенты[],4,0)="Основа",VLOOKUP(Рецепты[[#This Row],[Способ]],Способ[],2,0),0%) -> 0 | M33: =VLOOKUP(Рецепты[[#This Row],[Способ]],Способ[],3,0) -> 0.7 | N33: =Рецепты[[#This Row],[р]]*100%/(100%-Рецепты[[#This Row],[Потери, %]])+Рецепты[[#This Row],[Маржа]]*(Рецепты[[#This Row],[р]]*100%)/(100%-Рецепты[[#This Row],[Потери, %]]) -> 0.6545 | O33: =Рецепты[[#This Row],[Цена за 1 кг]]-(Рецепты[[#This Row],[р]]*100%/(100%-Рецепты[[#This Row],[Потери, %]])) -> 0.2695 | P33: https://www.youtube.com/watch?v=Mu_glCpe-Y8 | Q33: D:\Video\Колбаса_рецепты\Сочные домашние сардельки Кнакеры. Как сделать корочку, чтобы сардельки ''хрупали'' при укусе..mp7 | R33: =VLOOKUP(Рецепты[[#This Row],[Состав]],Ингредиенты[],9,0) -> Да
A34: Сардельки Свиные | B34: =B33 -> Сосиски | C34: =C33 -> Вареное | D34: Соль нитритная | E34: =VLOOKUP(Рецепты[[#This Row],[Состав]],Ингредиенты[],2,0) -> Специи | F34: 0.01 | G34: =IF(Рецепты[[#This Row],[%]]*1000>0,Рецепты[[#This Row],[%]]*1000,"") -> 10 | H34: =IFERROR(VLOOKUP(Рецепты[[#This Row],[Состав]],Ингредиенты!A:I,3,0)*Рецепты[[#This Row],[г]],"") -> 1.28 | I34: =СводРецепт!$A$1 -> 1000 | J34: =Рецепты[[#This Row],[%]]*Рецепты[[#This Row],[Масса]] -> 10 | K34: =Рецепты[[#This Row],[Вес ингр-тов]]*VLOOKUP(Рецепты[[#This Row],[Состав]],Ингредиенты[],3,FALSE) -> 1.28 | L34: =IF(VLOOKUP(Рецепты[[#This Row],[Состав]],Ингредиенты[],4,0)="Основа",VLOOKUP(Рецепты[[#This Row],[Способ]],Способ[],2,0),0%) -> 0 | M34: =VLOOKUP(Рецепты[[#This Row],[Способ]],Способ[],3,0) -> 0.7 | N34: =Рецепты[[#This Row],[р]]*100%/(100%-Рецепты[[#This Row],[Потери, %]])+Рецепты[[#This Row],[Маржа]]*(Рецепты[[#This Row],[р]]*100%)/(100%-Рецепты[[#This Row],[Потери, %]]) -> 2.176 | O34: =Рецепты[[#This Row],[Цена за 1 кг]]-(Рецепты[[#This Row],[р]]*100%/(100%-Рецепты[[#This Row],[Потери, %]])) -> 0.896 | P34: https://www.youtube.com/watch?v=Mu_glCpe-Y8 | Q34: D:\Video\Колбаса_рецепты\Сочные домашние сардельки Кнакеры. Как сделать корочку, чтобы сардельки ''хрупали'' при укусе..mp8 | R34: =VLOOKUP(Рецепты[[#This Row],[Состав]],Ингредиенты[],9,0) -> Да
A35: Сардельки Свиные | B35: =B34 -> Сосиски | C35: =C34 -> Вареное | D35: Сахар | E35: =VLOOKUP(Рецепты[[#This Row],[Состав]],Ингредиенты[],2,0) -> Специи | F35: 0.002 | G35: =IF(Рецепты[[#This Row],[%]]*1000>0,Рецепты[[#This Row],[%]]*1000,"") -> 2 | H35: =IFERROR(VLOOKUP(Рецепты[[#This Row],[Состав]],Ингредиенты!A:I,3,0)*Рецепты[[#This Row],[г]],"") -> 0.16176471 | I35: =СводРецепт!$A$1 -> 1000 | J35: =Рецепты[[#This Row],[%]]*Рецепты[[#This Row],[Масса]] -> 2 | K35: =Рецепты[[#This Row],[Вес ингр-тов]]*VLOOKUP(Рецепты[[#This Row],[Состав]],Ингредиенты[],3,FALSE) -> 0.16176471 | L35: =IF(VLOOKUP(Рецепты[[#This Row],[Состав]],Ингредиенты[],4,0)="Основа",VLOOKUP(Рецепты[[#This Row],[Способ]],Способ[],2,0),0%) -> 0 | M35: =VLOOKUP(Рецепты[[#This Row],[Способ]],Способ[],3,0) -> 0.7 | N35: =Рецепты[[#This Row],[р]]*100%/(100%-Рецепты[[#This Row],[Потери, %]])+Рецепты[[#This Row],[Маржа]]*(Рецепты[[#This Row],[р]]*100%)/(100%-Рецепты[[#This Row],[Потери, %]]) -> 0.275 | O35: =Рецепты[[#This Row],[Цена за 1 кг]]-(Рецепты[[#This Row],[р]]*100%/(100%-Рецепты[[#This Row],[Потери, %]])) -> 0.11323529 | P35: https://www.youtube.com/watch?v=Mu_glCpe-Y8 | Q35: D:\Video\Колбаса_рецепты\Сочные домашние сардельки Кнакеры. Как сделать корочку, чтобы сардельки ''хрупали'' при укусе..mp9 | R35: =VLOOKUP(Рецепты[[#This Row],[Состав]],Ингредиенты[],9,0) -> Да
A36: Сардельки Свиные | B36: =B35 -> Сосиски | C36: =C35 -> Вареное | D36: Перец черный молотый | E36: =VLOOKUP(Рецепты[[#This Row],[Состав]],Ингредиенты[],2,0) -> Специи | F36: 0.0013 | G36: =IF(Рецепты[[#This Row],[%]]*1000>0,Рецепты[[#This Row],[%]]*1000,"") -> 1.3 | H36: =IFERROR(VLOOKUP(Рецепты[[#This Row],[Состав]],Ингредиенты!A:I,3,0)*Рецепты[[#This Row],[г]],"") -> 1.4229091 | I36: =СводРецепт!$A$1 -> 1000 | J36: =Рецепты[[#This Row],[%]]*Рецепты[[#This Row],[Масса]] -> 1.3 | K36: =Рецепты[[#This Row],[Вес ингр-тов]]*VLOOKUP(Рецепты[[#This Row],[Состав]],Ингредиенты[],3,FALSE) -> 1.4229091 | L36: =IF(VLOOKUP(Рецепты[[#This Row],[Состав]],Ингредиенты[],4,0)="Основа",VLOOKUP(Рецепты[[#This Row],[Способ]],Способ[],2,0),0%) -> 0 | M36: =VLOOKUP(Рецепты[[#This Row],[Способ]],Способ[],3,0) -> 0.7 | N36: =Рецепты[[#This Row],[р]]*100%/(100%-Рецепты[[#This Row],[Потери, %]])+Рецепты[[#This Row],[Маржа]]*(Рецепты[[#This Row],[р]]*100%)/(100%-Рецепты[[#This Row],[Потери, %]]) -> 2.4189455 | O36: =Рецепты[[#This Row],[Цена за 1 кг]]-(Рецепты[[#This Row],[р]]*100%/(100%-Рецепты[[#This Row],[Потери, %]])) -> 0.99603636 | P36: https://www.youtube.com/watch?v=Mu_glCpe-Y8 | Q36: D:\Video\Колбаса_рецепты\Сочные домашние сардельки Кнакеры. Как сделать корочку, чтобы сардельки ''хрупали'' при укусе..mp10 | R36: =VLOOKUP(Рецепты[[#This Row],[Состав]],Ингредиенты[],9,0) -> Да
A37: Сардельки Свиные | B37: =B36 -> Сосиски | C37: =C36 -> Вареное | D37: Кориандр | E37: =VLOOKUP(Рецепты[[#This Row],[Состав]],Ингредиенты[],2,0) -> Специи | F37: 0.0013 | G37: =IF(Рецепты[[#This Row],[%]]*1000>0,Рецепты[[#This Row],[%]]*1000,"") -> 1.3 | H37: =IFERROR(VLOOKUP(Рецепты[[#This Row],[Состав]],Ингредиенты!A:I,3,0)*Рецепты[[#This Row],[г]],"") -> 0.65288889 | I37: =СводРецепт!$A$1 -> 1000 | J37: =Рецепты[[#This Row],[%]]*Рецепты[[#This Row],[Масса]] -> 1.3 | K37: =Рецепты[[#This Row],[Вес ингр-тов]]*VLOOKUP(Рецепты[[#This Row],[Состав]],Ингредиенты[],3,FALSE) -> 0.65288889 | L37: =IF(VLOOKUP(Рецепты[[#This Row],[Состав]],Ингредиенты[],4,0)="Основа",VLOOKUP(Рецепты[[#This Row],[Способ]],Способ[],2,0),0%) -> 0 | M37: =VLOOKUP(Рецепты[[#This Row],[Способ]],Способ[],3,0) -> 0.7 | N37: =Рецепты[[#This Row],[р]]*100%/(100%-Рецепты[[#This Row],[Потери, %]])+Рецепты[[#This Row],[Маржа]]*(Рецепты[[#This Row],[р]]*100%)/(100%-Рецепты[[#This Row],[Потери, %]]) -> 1.1099111 | O37: =Рецепты[[#This Row],[Цена за 1 кг]]-(Рецепты[[#This Row],[р]]*100%/(100%-Рецепты[[#This Row],[Потери, %]])) -> 0.45702222 | P37: https://www.youtube.com/watch?v=Mu_glCpe-Y8 | Q37: D:\Video\Колбаса_рецепты\Сочные домашние сардельки Кнакеры. Как сделать корочку, чтобы сардельки ''хрупали'' при укусе..mp11 | R37: =VLOOKUP(Рецепты[[#This Row],[Состав]],Ингредиенты[],9,0) -> Да
A38: Сардельки Свиные | B38: =B37 -> Сосиски | C38: =C37 -> Вареное | D38: Фосфат | E38: =VLOOKUP(Рецепты[[#This Row],[Состав]],Ингредиенты[],2,0) -> Специи | F38: 0.003 | G38: =IF(Рецепты[[#This Row],[%]]*1000>0,Рецепты[[#This Row],[%]]*1000,"") -> 3 | H38: =IFERROR(VLOOKUP(Рецепты[[#This Row],[Состав]],Ингредиенты!A:I,3,0)*Рецепты[[#This Row],[г]],"") -> 2.244 | I38: =СводРецепт!$A$1 -> 1000 | J38: =Рецепты[[#This Row],[%]]*Рецепты[[#This Row],[Масса]] -> 3 | K38: =Рецепты[[#This Row],[Вес ингр-тов]]*VLOOKUP(Рецепты[[#This Row],[Состав]],Ингредиенты[],3,FALSE) -> 2.244 | L38: =IF(VLOOKUP(Рецепты[[#This Row],[Состав]],Ингредиенты[],4,0)="Основа",VLOOKUP(Рецепты[[#This Row],[Способ]],Способ[],2,0),0%) -> 0 | M38: =VLOOKUP(Рецепты[[#This Row],[Способ]],Способ[],3,0) -> 0.7 | N38: =Рецепты[[#This Row],[р]]*100%/(100%-Рецепты[[#This Row],[Потери, %]])+Рецепты[[#This Row],[Маржа]]*(Рецепты[[#This Row],[р]]*100%)/(100%-Рецепты[[#This Row],[Потери, %]]) -> 3.8148 | O38: =Рецепты[[#This Row],[Цена за 1 кг]]-(Рецепты[[#This Row],[р]]*100%/(100%-Рецепты[[#This Row],[Потери, %]])) -> 1.5708 | P38: https://www.youtube.com/watch?v=Mu_glCpe-Y8 | Q38: D:\Video\Колбаса_рецепты\Сочные домашние сардельки Кнакеры. Как сделать корочку, чтобы сардельки ''хрупали'' при укусе..mp12 | R38: =VLOOKUP(Рецепты[[#This Row],[Состав]],Ингредиенты[],9,0) -> Да
A39: Сардельки Свиные | B39: =B38 -> Сосиски | C39: =C38 -> Вареное | D39: Чеснок сушеный | E39: =VLOOKUP(Рецепты[[#This Row],[Состав]],Ингредиенты[],2,0) -> Специи | F39: 0.0006 | G39: =IF(Рецепты[[#This Row],[%]]*1000>0,Рецепты[[#This Row],[%]]*1000,"") -> 0.6 | H39: =IFERROR(VLOOKUP(Рецепты[[#This Row],[Состав]],Ингредиенты!A:I,3,0)*Рецепты[[#This Row],[г]],"") -> 0.527 | I39: =СводРецепт!$A$1 -> 1000 | J39: =Рецепты[[#This Row],[%]]*Рецепты[[#This Row],[Масса]] -> 0.6 | K39: =Рецепты[[#This Row],[Вес ингр-тов]]*VLOOKUP(Рецепты[[#This Row],[Состав]],Ингредиенты[],3,FALSE) -> 0.527 | L39: =IF(VLOOKUP(Рецепты[[#This Row],[Состав]],Ингредиенты[],4,0)="Основа",VLOOKUP(Рецепты[[#This Row],[Способ]],Способ[],2,0),0%) -> 0 | M39: =VLOOKUP(Рецепты[[#This Row],[Способ]],Способ[],3,0) -> 0.7 | N39: =Рецепты[[#This Row],[р]]*100%/(100%-Рецепты[[#This Row],[Потери, %]])+Рецепты[[#This Row],[Маржа]]*(Рецепты[[#This Row],[р]]*100%)/(100%-Рецепты[[#This Row],[Потери, %]]) -> 0.8959 | O39: =Рецепты[[#This Row],[Цена за 1 кг]]-(Рецепты[[#This Row],[р]]*100%/(100%-Рецепты[[#This Row],[Потери, %]])) -> 0.3689 | P39: https://www.youtube.com/watch?v=Mu_glCpe-Y8 | Q39: D:\Video\Колбаса_рецепты\Сочные домашние сардельки Кнакеры. Как сделать корочку, чтобы сардельки ''хрупали'' при укусе..mp13 | R39: =VLOOKUP(Рецепты[[#This Row],[Состав]],Ингредиенты[],9,0) -> Да
A40: Сардельки Свиные | B40: =B39 -> Сосиски | C40: =C39 -> Вареное | D40: Свиная черева 32/34 | E40: =VLOOKUP(Рецепты[[#This Row],[Состав]],Ингредиенты[],2,0) -> Оболочка | F40: 0.001 | G40: =IF(Рецепты[[#This Row],[%]]*1000>0,Рецепты[[#This Row],[%]]*1000,"") -> 1 | H40: =IFERROR(VLOOKUP(Рецепты[[#This Row],[Состав]],Ингредиенты!A:I,3,0)*Рецепты[[#This Row],[г]],"") -> 39.348206 | I40: =СводРецепт!$A$1 -> 1000 | J40: =Рецепты[[#This Row],[%]]*Рецепты[[#This Row],[Масса]] -> 1 | K40: =Рецепты[[#This Row],[Вес ингр-тов]]*VLOOKUP(Рецепты[[#This Row],[Состав]],Ингредиенты[],3,FALSE) -> 39.348206 | L40: =IF(VLOOKUP(Рецепты[[#This Row],[Состав]],Ингредиенты[],4,0)="Основа",VLOOKUP(Рецепты[[#This Row],[Способ]],Способ[],2,0),0%) -> 0 | M40: =VLOOKUP(Рецепты[[#This Row],[Способ]],Способ[],3,0) -> 0.7 | N40: =Рецепты[[#This Row],[р]]*100%/(100%-Рецепты[[#This Row],[Потери, %]])+Рецепты[[#This Row],[Маржа]]*(Рецепты[[#This Row],[р]]*100%)/(100%-Рецепты[[#This Row],[Потери, %]]) -> 66.891951 | O40: =Рецепты[[#This Row],[Цена за 1 кг]]-(Рецепты[[#This Row],[р]]*100%/(100%-Рецепты[[#This Row],[Потери, %]])) -> 27.543745 | P40: https://www.youtube.com/watch?v=Mu_glCpe-Y8 | Q40: D:\Video\Колбаса_рецепты\Сочные домашние сардельки Кнакеры. Как сделать корочку, чтобы сардельки ''хрупали'' при укусе..mp14 | R40: =VLOOKUP(Рецепты[[#This Row],[Состав]],Ингредиенты[],9,0) -> Нет
A41: Курица ГК | B41: Цельное | C41: ГК | D41: Курица целая | E41: =VLOOKUP(Рецепты[[#This Row],[Состав]],Ингредиенты[],2,0) -> Птица | F41: 1 | G41: =IF(Рецепты[[#This Row],[%]]*1000>0,Рецепты[[#This Row],[%]]*1000,"") -> 1000 | H41: =IFERROR(VLOOKUP(Рецепты[[#This Row],[Состав]],Ингредиенты!A:I,3,0)*Рецепты[[#This Row],[г]],"") -> 200 | I41: =СводРецепт!$A$1 -> 1000 | J41: =Рецепты[[#This Row],[%]]*Рецепты[[#This Row],[Масса]] -> 1000 | K41: =Рецепты[[#This Row],[Вес ингр-тов]]*VLOOKUP(Рецепты[[#This Row],[Состав]],Ингредиенты[],3,FALSE) -> 200 | L41: =IF(VLOOKUP(Рецепты[[#This Row],[Состав]],Ингредиенты[],4,0)="Основа",VLOOKUP(Рецепты[[#This Row],[Способ]],Способ[],2,0),0%) -> 0.15 | M41: =VLOOKUP(Рецепты[[#This Row],[Способ]],Способ[],3,0) -> 0.9 | N41: =Рецепты[[#This Row],[р]]*100%/(100%-Рецепты[[#This Row],[Потери, %]])+Рецепты[[#This Row],[Маржа]]*(Рецепты[[#This Row],[р]]*100%)/(100%-Рецепты[[#This Row],[Потери, %]]) -> 447.05882 | O41: =Рецепты[[#This Row],[Цена за 1 кг]]-(Рецепты[[#This Row],[р]]*100%/(100%-Рецепты[[#This Row],[Потери, %]])) -> 211.76471 | P41: https://www.youtube.com/watch?v=bwqN7FZs5Ds | Q41: D:\Video\Колбаса_рецепты\КУРИЦА горячего копчения в коптильне уэк москит.mp4 | R41: =VLOOKUP(Рецепты[[#This Row],[Состав]],Ингредиенты[],9,0) -> Да
A42: Курица ГК | B42: =B41 -> Цельное | C42: =C41 -> ГК | D42: Вода | E42: =VLOOKUP(Рецепты[[#This Row],[Состав]],Ингредиенты[],2,0) -> Добавки | F42: 0.1 | G42: =IF(Рецепты[[#This Row],[%]]*1000>0,Рецепты[[#This Row],[%]]*1000,"") -> 100 | H42: =IFERROR(VLOOKUP(Рецепты[[#This Row],[Состав]],Ингредиенты!A:I,3,0)*Рецепты[[#This Row],[г]],"") -> 0.1 | I42: =СводРецепт!$A$1 -> 1000 | J42: =Рецепты[[#This Row],[%]]*Рецепты[[#This Row],[Масса]] -> 100 | K42: =Рецепты[[#This Row],[Вес ингр-тов]]*VLOOKUP(Рецепты[[#This Row],[Состав]],Ингредиенты[],3,FALSE) -> 0.1 | L42: =IF(VLOOKUP(Рецепты[[#This Row],[Состав]],Ингредиенты[],4,0)="Основа",VLOOKUP(Рецепты[[#This Row],[Способ]],Способ[],2,0),0%) -> 0 | M42: =VLOOKUP(Рецепты[[#This Row],[Способ]],Способ[],3,0) -> 0.9 | N42: =Рецепты[[#This Row],[р]]*100%/(100%-Рецепты[[#This Row],[Потери, %]])+Рецепты[[#This Row],[Маржа]]*(Рецепты[[#This Row],[р]]*100%)/(100%-Рецепты[[#This Row],[Потери, %]]) -> 0.19 | O42: =Рецепты[[#This Row],[Цена за 1 кг]]-(Рецепты[[#This Row],[р]]*100%/(100%-Рецепты[[#This Row],[Потери, %]])) -> 0.09 | P42: https://www.youtube.com/watch?v=AyC9SVj43Sg | Q42: D:\Video\Колбаса_рецепты\ХИТ!!! Курица копчено-вареная. Как правильно шприцевать и коптить. Как сделать золотистую корочку.mp4 | R42: =VLOOKUP(Рецепты[[#This Row],[Состав]],Ингредиенты[],9,0) -> Да
A43: Курица ГК | B43: =B42 -> Цельное | C43: =C42 -> ГК | D43: Соль пищевая | E43: =VLOOKUP(Рецепты[[#This Row],[Состав]],Ингредиенты[],2,0) -> Специи | F43: 0.009 | G43: =IF(Рецепты[[#This Row],[%]]*1000>0,Рецепты[[#This Row],[%]]*1000,"") -> 9 | H43: =IFERROR(VLOOKUP(Рецепты[[#This Row],[Состав]],Ингредиенты!A:I,3,0)*Рецепты[[#This Row],[г]],"") -> 0.3465 | I43: =СводРецепт!$A$1 -> 1000 | J43: =Рецепты[[#This Row],[%]]*Рецепты[[#This Row],[Масса]] -> 9 | K43: =Рецепты[[#This Row],[Вес ингр-тов]]*VLOOKUP(Рецепты[[#This Row],[Состав]],Ингредиенты[],3,FALSE) -> 0.3465 | L43: =IF(VLOOKUP(Рецепты[[#This Row],[Состав]],Ингредиенты[],4,0)="Основа",VLOOKUP(Рецепты[[#This Row],[Способ]],Способ[],2,0),0%) -> 0 | M43: =VLOOKUP(Рецепты[[#This Row],[Способ]],Способ[],3,0) -> 0.9 | N43: =Рецепты[[#This Row],[р]]*100%/(100%-Рецепты[[#This Row],[Потери, %]])+Рецепты[[#This Row],[Маржа]]*(Рецепты[[#This Row],[р]]*100%)/(100%-Рецепты[[#This Row],[Потери, %]]) -> 0.65835 | O43: =Рецепты[[#This Row],[Цена за 1 кг]]-(Рецепты[[#This Row],[р]]*100%/(100%-Рецепты[[#This Row],[Потери, %]])) -> 0.31185 | P43: https://www.youtube.com/watch?v=AyC9SVj43Sg | Q43: D:\Video\Колбаса_рецепты\ХИТ!!! Курица копчено-вареная. Как правильно шприцевать и коптить. Как сделать золотистую корочку.mp5 | R43: =VLOOKUP(Рецепты[[#This Row],[Состав]],Ингредиенты[],9,0) -> Да
